Workbook

Sheet Summary
C3: Current Assumptions | G3: Exit Upside
B5: Ticker | C5: Current Date | D5: Share Price | E5: 2025E EV / EBITDA | F5: 2026E EV / EBITDA | G5: Exit Date | H5: EV / EBITDA | I5: Share Price | J5: IRR | K5: MOIC
B6: BABA | C6: 45917 | D6: 166 | E6: =BABA!C29 -> 12.815645 | F6: =BABA!C30 -> 11.06475 | G6: 47848 | H6: 15 | I6: =BABA!C42 -> 413.12504 | J6: =BABA!C48 -> 0.18808465 | K6: =BABA!C47 -> 2.488705
B7: AMZN | C7: =C9 -> 45917 | D7: 234.05 | E7: =AMZN!F8 -> 15.406567 | F7: =AMZN!F9 -> 12.882062 | G7: 47848 | H7: 15 | I7: =AMZN!F19 -> 605.83516 | J7: =AMZN!F24 -> 0.19694565 | K7: =AMZN!F23 -> 2.5884861
B8: FOUR | C8: 46113 | D8: 42.56 | E8: =FOUR!F8 -> 8.3126804 | F8: =FOUR!F9 -> 6.7758824 | G8: 47848 | H8: 10 | I8: =FOUR!F19 -> 284.07553 | J8: =FOUR!F24 -> 0.49086949 | K8: =FOUR!F23 -> 6.674707
B9: WBD | C9: =C6 -> 45917 | D9: 18 | E9: =WBD!C8 -> 8.9869441 | F9: =WBD!C9 -> 8.7111679 | G9: 47848 | H9: 10 | I9: =WBD!C18 -> 36.513268 | J9: =WBD!C23 -> 0.14304467 | K9: =WBD!C22 -> 2.0285149
B10: XPOF | C10: =C8 -> 46113 | D10: 8.41 | E10: =XPOF!F8 -> 6.2264071 | F10: =XPOF!F9 -> 5.7866372 | G10: 47848 | H10: 8 | I10: =XPOF!F19 -> 30.297391 | J10: =XPOF!F24 -> 0.30947276 | K10: =XPOF!F23 -> 3.6025435
B11: ST | C11: =ST!A2 -> 46113 | D11: =ST!F3 -> 32.45 | E11: =ST!F9 -> 8.3720656 | F11: =ST!F10 -> 8.0061281 | G11: =ST!A12 -> 47848 | H11: =ST!F14 -> 10 | I11: =ST!F20 -> 101.70669 | J11: =ST!F25 -> 0.27166928 | K11: =ST!F24 -> 3.1342584
B12: RDDT | C12: =C11 -> 46113 | D12: 131.84 | E12: =RDDT!F65 -> 20.788132 | F12: =RDDT!F66 -> 13.810375 | G12: 48213 | H12: 18 | I12: =RDDT!F76 -> 453.74602 | J12: =RDDT!F82 -> 0.23951154 | K12: =RDDT!F81 -> 3.4416415

Sheet BABA
B1: FX | C1: 0.14
B2: (RMB, FYE March) | C2: FY2022A | D2: FY2023A | E2: FY2024A | F2: FY2025A
B3: Revenue
B4: TTG (Taobao & Tmall Group) | C4: 591.58 | D4: 582.731 | E4: 434.893 | F4: 449.827
B5: Cloud Intelligence Group | C5: 74.568 | D5: 77.203 | E5: 106.374 | F5: 118.028
B6: AIDC (International Commerce) | C6: 61.078 | D6: 69.204 | E6: 102.598 | F6: 132.3
B7: Cainiao (Smart Logistics) | C7: 46.107 | D7: 55.681 | E7: 99.02 | F7: 101.272
B8: Local Services | C8: 44.616 | D8: 50.112 | E8: 59.802 | F8: 67.076
B9: All Others | C9: =C10-SUM(C4:C8) -> 35.113 | D9: =D10-SUM(D4:D8) -> 33.756 | E9: =E10-SUM(E4:E8) -> 138.481 | F9: =F10-SUM(F4:F8) -> 127.844
B10: Consolidated Total | C10: 853.062 | D10: 868.687 | E10: 941.168 | F10: 996.347
B12: EBITA
B13: TTG (Taobao & Tmall Group) | C13: 182.431 | D13: 184.862 | E13: 194.827 | F13: 196.232
B14: Cloud Intelligence Group | C14: 1.146 | D14: 1.422 | E14: 6.121 | F14: 10.556
B15: AIDC (International Commerce) | C15: -8.991 | D15: -5.62 | E15: -8.035 | F15: -15.137
B16: Cainiao (Smart Logistics) | C16: -1.465 | D16: -0.391 | E16: 1.402 | F16: 0.302
B17: Local Services | C17: -22.092 | D17: -14.021 | E17: -9.812 | F17: -3.689
B18: All Others | C18: =C19-SUM(C13:C17) -> #VALUE! | D18: =D19-SUM(D13:D17) -> -18.341 | E18: =E19-SUM(E13:E17) -> -19.475 | F18: =F19-SUM(F13:F17) -> -15.199
B19: Consolidated Total | C19: =SUM(C13:C18) -> #VALUE! | D19: 147.911 | E19: 165.028 | F19: 173.065
A21: =Summary!C6 -> 45917 | B21: Current Capitalization
B22: Current Share Price | C22: =Summary!D6 -> 166
B23: Shares Outstanding | C23: 2270.6467
B24: Market Cap | C24: =C22*C23 -> 376927.36
B25: (+) Debt | C25: 34625.2
B26: (-) Cash | C26: -59742
B27: (+) Minority Interest | C27: 11199
B28: TEV | C28: =SUM(C24:C27) -> 363009.56
B29: 2025E EV / EBITDA | C29: =C28/(F86*1000) -> 12.815645
B30: 2026E EV / EBITDA | C30: =C28/(G86*1000) -> 11.06475
A32: =Summary!G6 -> 47848 | B32: Exit Upside
B33: FY2030E EBITDA | C33: =K86*1000 -> 52900.066
B34: Multiple | C34: =Summary!H6 -> 15
B35: TEV | C35: =C33*C34 -> 793500.99
B36: (-) Current Debt | C36: =-C25 -> -34625.2
B37: (+) Current Cash | C37: =-C26 -> 59742
B38: (-) Current Minority Interest | C38: =-C27 -> -11199
B39: (+) Cumulative Levered FCF | C39: =C57 -> 130642.22
B40: Market Cap | C40: =SUM(C35:C39) -> 938061.02
B41: Current Shares Outstanding | C41: =C23 -> 2270.6467
A42: =A32 -> 47848 | B42: Implied Share Price | C42: =C40/C41 -> 413.12504
A43: =A21 -> 45917 | B43: Current Share Price | C43: =C22 -> 166
...

Sheet AMZN
A2: =Summary!C7 -> 45917 | B2: Current Capitalization
B3: Current Share Price | F3: =Summary!D7 -> 234.05
B4: Diluted Shares Outstanding | F4: 10.664912
B5: Market Cap | F5: =F3*F4 -> 2496.1227
B6: (+) Net Debt | F6: =F7-F5 -> 66.39
B7: TEV | F7: 2562.5127
B8: 2025E EV / EBITDA | F8: =F7/E53 -> 15.406567
B9: 2026E EV / EBITDA | F9: =F7/F53 -> 12.882062
A11: =Summary!G7 -> 47848 | B11: Exit
B12: 2030E EBITDA | F12: =J53 -> 384.0045
B13: EV / EBITDA | F13: =Summary!H7 -> 15
B14: TEV | F14: =F12*F13 -> 5760.0674
B15: (-) Current Net Debt | F15: =-F6 -> -66.39
B16: (+) Cumulative Levered FCF | F16: =F32 -> 767.50141
B17: Market Cap | F17: =SUM(F14:F16) -> 6461.1788
B18: Current Shares Outstanding | F18: =F4 -> 10.664912
B19: Implied Share Price | F19: =F17/F18 -> 605.83516
B21: Remaining Upside
B22: Gross Upside | F22: =F19/F3-1 -> 1.5884861
B23: MOIC | F23: =F19/F3 -> 2.5884861
A24: =(A11-A2)/365 -> 5.290411 | B24: IRR | F24: =F23^(1/A24)-1 -> 0.19694565
B26: Memo: Cash Flows
B27: Cumulative EBITDA | F27: =SUM(F53:J53) -> 1418.2307
B28: Cumulative D&A | F28: =SUM(F57:J57) -> 635.636
A29: 2.5 | B29: Cumulative Interest Expense | F29: =A29*5 -> 12.5
B30: Cumulative Capex | F30: =SUM(F60:J60) -> 559.96979
A31: 0.1 | B31: Cumulative Taxes | F31: =(F27-F28)*A31 -> 78.259466
B32: Cumulative Levered FCF | F32: =F27-SUM(F29:F31) -> 767.50141
K34: '25E - '30E
C35: 2023A | D35: 2024A | E35: 2025E | F35: 2026E | G35: 2027E | H35: 2028E | I35: 2029E | J35: 2030E | K35: CAGR
B36: Revenue
B37: North America | C37: 353 | D37: 388
B38: International | C38: 131 | D38: 143
B39: AWS | C39: 91 | D39: 108
B40: Total | C40: =SUM(C37:C39) -> 575 | D40: =SUM(D37:D39) -> 639 | E40: 708.046 | F40: 779.6 | G40: 861.758 | H40: =G40*(1+H41) -> 947.9338 | I40: =H40*(1+I41) -> 1042.7272 | J40: =I40*(1+J41) -> 1146.9999 | K40: =(J40/E40)^(1/5)-1 -> 0.10128667
B41: % Growth | D41: =D40/C40-1 -> 0.11130435 | E41: =E40/D40-1 -> 0.10805321 | F41: =F40/E40-1 -> 0.10105841 | G41: =G40/F40-1 -> 0.10538481 | H41: 0.1 | I41: 0.1 | J41: 0.1
B43: Operating Income
B44: North America | C44: 15 | D44: 25
B45: International | C45: -3 | D45: 4
B46: AWS | C46: 25 | D46: 40
...

Sheet FOUR
A2: =Summary!C8 -> 46113 | B2: Current Capitalization
B3: Current Share Price | F3: =Summary!D8 -> 42.56
B4: Diluted Shares Outstanding | F4: 73.5
B5: Market Cap | F5: =F3*F4 -> 3128.16
B6: (+) Net Debt | F6: 3500
B7: TEV | F7: 8063.3
B8: 2025E EV / EBITDA | F8: =F7/E41 -> 8.3126804
B9: 2026E EV / EBITDA | F9: =F7/F41 -> 6.7758824
A11: =Summary!G8 -> 47848 | B11: Exit
B12: 2030E EBITDA | F12: =J41 -> 1850
B13: EV / EBITDA | F13: 10
B14: TEV | F14: =F12*F13 -> 18500
B15: (-) Current Net Debt | F15: =-F6 -> -3500
B16: (+) Cumulative Levered FCF | F16: =F32 -> 5879.5515
B17: Market Cap | F17: =SUM(F14:F16) -> 20879.552
B18: Current Shares Outstanding | F18: =F4 -> 73.5
B19: Implied Share Price | F19: =F17/F18 -> 284.07553
B21: Remaining Upside
B22: Gross Upside | F22: =F19/F3-1 -> 5.674707
B23: MOIC | F23: =F19/F3 -> 6.674707
A24: =(A11-A2)/365 -> 4.7534247 | B24: IRR | F24: =F23^(1/A24)-1 -> 0.49086949
B26: Memo: Cash Flows
B27: Cumulative EBITDA | F27: =SUM(F41:J41) -> 8387
B28: Cumulative D&A | F28: =SUM(F45:J45) -> 4635.41
A29: 175 | B29: Cumulative Interest Expense | F29: =A29*5 -> 875
B30: Cumulative Capex | F30: =SUM(F48:J48) -> 1069.71
A31: 0.15 | B31: Cumulative Taxes | F31: =(F27-F28)*A31 -> 562.7385
B32: Cumulative Levered FCF | F32: =F27-SUM(F29:F31) -> 5879.5515
K34: '25E - '30E
C35: 2023A | D35: 2024A | E35: 2025E | F35: 2026E | G35: 2027E | H35: 2028E | I35: 2029E | J35: 2030E | K35: CAGR
B36: Revenue
B37: Total | C37: 2565 | D37: 3331 | E37: 4180 | F37: 5100 | G37: 6120 | H37: 7037 | I37: 8093 | J37: 9307 | K37: =(J37/E37)^(1/5)-1 -> 0.1736178
B38: % Growth | D38: =D37/C37-1 -> 0.29863548 | E38: =E37/D37-1 -> 0.25487841 | F38: =F37/E37-1 -> 0.22009569 | G38: =G37/F37-1 -> 0.2 | H38: 0.15 | I38: 0.15 | J38: 0.15
B40: EBITDA
B41: Total | C41: 376 | D41: 542 | E41: 970 | F41: 1190 | G41: 1580 | H41: 1777 | I41: 1990 | J41: 1850 | K41: =(J41/E41)^(1/5)-1 -> 0.13783686
B42: % Growth | D42: =D41/C41-1 -> 0.44148936 | E42: =E41/D41-1 -> 0.7896679 | F42: =F41/E41-1 -> 0.22680412 | G42: =G41/F41-1 -> 0.32773109 | H42: =H41/G41-1 -> 0.12468354 | I42: =I41/H41-1 -> 0.11986494 | J42: =J41/I41-1 -> -0.070351759
B43: % Margin | C43: =C41/C37 -> 0.14658869 | D43: =D41/D37 -> 0.1627139 | E43: =E41/E37 -> 0.23205742 | F43: =F41/F37 -> 0.23333333 | G43: =G41/G37 -> 0.25816993 | H43: =H41/H37 -> 0.25252238 | I43: =I41/I37 -> 0.24589151 | J43: =J41/J37 -> 0.19877512
B45: D&A | C45: 196 | D45: 271 | E45: 523 | F45: =F46*F37 -> 663 | G45: =G46*G37 -> 795.6 | H45: =H46*H37 -> 914.81 | I45: =I46*I37 -> 1052.09 | J45: =J46*J37 -> 1209.91 | K45: =(J45/E45)^(1/5)-1 -> 0.18263377
B46: % Revenue | C46: =C45/C37 -> 0.076413255 | D46: =D45/D37 -> 0.08135695 | E46: =E45/E37 -> 0.12511962 | F46: 0.13 | G46: 0.13 | H46: 0.13 | I46: 0.13 | J46: 0.13
B48: Capex | C48: 92 | D48: 108 | E48: 115 | F48: =F49*F37 -> 153 | G48: =G49*G37 -> 183.6 | H48: =H49*H37 -> 211.11 | I48: =I49*I37 -> 242.79 | J48: =J49*J37 -> 279.21 | K48: =(J48/E48)^(1/5)-1 -> 0.1941163
...

Sheet WBD
B2: Current Capitalization
A3: =Summary!C9 -> 45917 | B3: Current Share Price | C3: =Summary!D9 -> 18
B4: (x) FDSO | C4: 2534.6633
B5: Market Cap | C5: =C3*C4 -> 45623.939
B6: (+) Net Debt | C6: 33578
B7: TEV | C7: =C5+C6 -> 79201.939
B8: 2025E EV / EBITDA | C8: =C7/F38 -> 8.9869441
B9: 2026E EV / EBITDA | C9: =C7/G38 -> 8.7111679
B11: Exit
A12: =Summary!G9 -> 47848 | B12: 2030E EBITDA | C12: =K38 -> 10549.584
B13: EV / EBITDA | C13: =Summary!H9 -> 10
B14: TEV | C14: =C12*C13 -> 105495.84
B15: (-) Net Debt | C15: =-K40 -> -12947
B16: Market Cap | C16: =C14+C15 -> 92548.839
B17: (/) FDSO | C17: =C4 -> 2534.6633
B18: Implied Share Price | C18: =C16/C17 -> 36.513268
B20: Remaining Upside
B21: Gross Upside | C21: =C18/C3-1 -> 1.0285149
B22: MOIC | C22: =C18/C3 -> 2.0285149
A23: =(A12-A3)/365 -> 5.290411 | B23: IRR | C23: =C22^(1/A23)-1 -> 0.14304467
C25: 2022A | D25: 2023A | E25: 2024A | F25: 2025E | G25: 2026E | H25: 2027E | I25: 2028E | J25: 2029E | K25: 2030E
B26: Revenue
B27: Studios | C27: 13798 | D27: 12192 | E27: 11607 | F27: 12126 | G27: 12445 | H27: =G27*(1+H57) -> 12818.35 | I27: =H27*(1+I57) -> 13202.9 | J27: =I27*(1+J57) -> 13598.988 | K27: =J27*(1+K57) -> 14006.957
B28: Networks | C28: 23186 | D28: 21244 | E28: 20175 | F28: 17153 | G28: 14917 | H28: =G28*(1+H58) -> 13425.3 | I28: =H28*(1+I58) -> 12082.77 | J28: =I28*(1+J58) -> 10874.493 | K28: =J28*(1+K58) -> 9787.0437
B29: DTC | C29: 9693 | D29: 10154 | E29: 10313 | F29: 11023 | G29: 11992 | H29: =G29*(1+H59) -> 13591.981 | I29: =H29*(1+I59) -> 15469.302 | J29: =I29*(1+J59) -> 17681.243 | K29: =J29*(1+K59) -> 20297.94
B30: Elims and Adj. | C30: =C31-SUM(C27:C29) -> -3582 | D30: =D31-SUM(D27:D29) -> -2269 | E30: =E31-SUM(E27:E29) -> -2774 | F30: =F31-SUM(F27:F29) -> -2639 | G30: =G31-SUM(G27:G29) -> -2679 | H30: =G30*(1+H60) -> -2679 | I30: =H30*(1+I60) -> -2679 | J30: =I30*(1+J60) -> -2679 | K30: =J30*(1+K60) -> -2679
B31: Total Revenue | C31: 43095 | D31: 41321 | E31: 39321 | F31: 37663 | G31: 36675 | H31: =SUM(H27:H30) -> 37156.631 | I31: =SUM(I27:I30) -> 38075.972 | J31: =SUM(J27:J30) -> 39475.724 | K31: =SUM(K27:K30) -> 41412.941
B33: Adj. EBITDA
B34: Studios | C34: 2749 | D34: 2183 | E34: 1652 | F34: 2028 | G34: 2463 | H34: =G34*(1+H64) -> 2709.3 | I34: =H34*(1+I64) -> 2980.23 | J34: =I34*(1+J64) -> 3278.253 | K34: =J34*(1+K64) -> 3606.0783
B35: Networks | C35: 7465 | D35: 9063 | E35: 8149 | F35: 7012 | G35: 6662 | H35: =G35*(1+H65) -> 6328.9 | I35: =H35*(1+I65) -> 6012.455 | J35: =I35*(1+J65) -> 5711.8323 | K35: =J35*(1+K65) -> 5426.2406
B36: DTC | C36: -1409 | D36: 103 | E36: 677 | F36: 1313 | G36: =F36+(G115/1000) -> 1779.3008 | H36: =G36+(H115/1000) -> 2034.6462 | I36: =H36+(I115/1000) -> 2366.9182 | J36: =I36+(J115/1000) -> 2792.1103 | K36: =J36+(K115/1000) -> 3329.5657
B37: Elims and Adj. | C37: =C38-SUM(C34:C36) -> -2012 | D37: =D38-SUM(D34:D36) -> -1149 | E37: =E38-SUM(E34:E36) -> -1446 | F37: =F38-SUM(F34:F36) -> -1540 | G37: =G38-SUM(G34:G36) -> -1812.3008 | H37: =G37*(1+H67) -> -1812.3008 | I37: =H37*(1+I67) -> -1812.3008 | J37: =I37*(1+J67) -> -1812.3008 | K37: =J37*(1+K67) -> -1812.3008
B38: Total Adj. EBITDA | C38: 6793 | D38: 10200 | E38: 9032 | F38: 8813 | G38: 9092 | H38: =SUM(H34:H37) -> 9260.5454 | I38: =SUM(I34:I37) -> 9547.3024 | J38: =SUM(J34:J37) -> 9969.8948 | K38: =SUM(K34:K37) -> 10549.584
A40: 3000 | B40: Net Debt | C40: 45268 | D40: 39889 | E40: 34193 | F40: 29811 | G40: 24947 | H40: =G40-$A$40 -> 21947 | I40: =H40-$A$40 -> 18947 | J40: =I40-$A$40 -> 15947 | K40: =J40-$A$40 -> 12947
B41: Net Leverage | C41: =C40/C38 -> 6.6639187 | D41: =D40/D38 -> 3.9106863 | E41: =E40/E38 -> 3.7857617 | F41: =F40/F38 -> 3.3826166 | G41: =G40/G38 -> 2.7438407 | H41: =H40/H38 -> 2.3699468 | I41: =I40/I38 -> 1.9845396 | J41: =J40/J38 -> 1.5995154 | K41: =K40/K38 -> 1.2272522
B43: DTC
B44: Domestic Subscribers | C44: 54600 | D44: 52000 | E44: 57100 | F44: 56850 | G44: 57600 | H44: =G44*(1+H92) -> 60480 | I44: =H44*(1+I92) -> 63504 | J44: =I44*(1+J92) -> 66679.2 | K44: =J44*(1+K92) -> 70013.16
B45: International Subscribers | C45: 42300 | D45: 45600 | E45: 59800 | F45: 70800 | G45: 92800 | H45: =G45*(1+H93) -> 111360 | I45: =H45*(1+I93) -> 133632 | J45: =I45*(1+J93) -> 160358.4 | K45: =J45*(1+K93) -> 192430.08
B46: Total DTC Subscribers | C46: =SUM(C44:C45) -> 96900 | D46: =SUM(D44:D45) -> 97600 | E46: =SUM(E44:E45) -> 116900 | F46: =SUM(F44:F45) -> 127650 | G46: =SUM(G44:G45) -> 150400 | H46: =SUM(H44:H45) -> 171840 | I46: =SUM(I44:I45) -> 197136 | J46: =SUM(J44:J45) -> 227037.6 | K46: =SUM(K44:K45) -> 262443.24
B48: Domestic DTC ARPU | C48: 10.63 | D48: 11.21 | E48: 11.89 | F48: 11.65 | G48: 11.65 | H48: =G48*(1+H96) -> 11.9995 | I48: =H48*(1+I96) -> 12.359485 | J48: =I48*(1+J96) -> 12.73027 | K48: =J48*(1+K96) -> 13.112178
...

Sheet XPOF
A2: =Summary!C10 -> 46113 | B2: Current Capitalization
B3: Current Share Price | F3: =Summary!D10 -> 8.41
B4: Diluted Shares Outstanding | F4: 49.144444
B5: Market Cap | F5: =F3*F4 -> 413.30478
B6: (+) Net Debt & NCI | F6: 271.6
B7: TEV | F7: =SUM(F5:F6) -> 684.90478
B8: 2025E EV / EBITDA | C8: =C7/F35 -> #DIV/0! | F8: =F7/G66 -> 6.2264071
B9: 2026E EV / EBITDA | C9: =C7/G35 -> #DIV/0! | F9: =F7/H66 -> 5.7866372
A11: =Summary!G10 -> 47848 | B11: Exit
B12: 2030E EBITDA | F12: =L66 -> 178.15627
B13: EV / EBITDA | F13: =Summary!H10 -> 8
B14: TEV | F14: =F12*F13 -> 1425.2502
B15: (-) Current Net Debt & NCI | F15: =-F6 -> -271.6
B16: (+) Cumulative Levered FCF | F16: =F32 -> 335.29828
B17: Market Cap | F17: =SUM(F14:F16) -> 1488.9484
B18: Current Shares Outstanding | F18: =F4 -> 49.144444
B19: Implied Share Price | F19: =F17/F18 -> 30.297391
B21: Remaining Upside
B22: Gross Upside | C22: =C18/C19-1 -> #DIV/0! | F22: =F19/F3-1 -> 2.6025435
B23: MOIC | C23: =C18/C19 -> #DIV/0! | F23: =F19/F3 -> 3.6025435
A24: =(A11-A2)/365 -> 4.7534247 | B24: IRR | C24: =C23^(1/A24)-1 -> #DIV/0! | F24: =F23^(1/A24)-1 -> 0.30947276
B26: Memo: Cash Flows
B27: Cumulative EBITDA | F27: =SUM(H66:L66) -> 726.54557
A28: 0.2 | B28: Cumulative D&A | F28: =A28*F27 -> 145.30911
A29: 50 | B29: Cumulative Interest Expense | F29: =A29*5 -> 250
A30: 5 | B30: Cumulative Capex | F30: =A30*5 -> 25
A31: 0.2 | B31: Cumulative Taxes | F31: =(F27-F28)*A31 -> 116.24729
B32: Cumulative Levered FCF | F32: =F27-SUM(F29:F31) -> 335.29828
B34: ($ in millions except per unit) | C34: 2021A | D34: 2022A | E34: 2023A | F34: 2024A | G34: 2025E | H34: 2026E | I34: 2027E | J34: 2028E | K34: 2029E | L34: 2030E | M34: '25E - '30E CAGR
B35: Studios
B36: Club Pilates | C36: 726 | D36: 953 | E36: 1109 | F36: 1200 | G36: =MROUND((1+G83)*F36,1) -> 1320 | H36: =MROUND((1+H83)*G36,1) -> 1452 | I36: =MROUND((1+I83)*H36,1) -> 1597 | J36: =MROUND((1+J83)*I36,1) -> 1757 | K36: =MROUND((1+K83)*J36,1) -> 1933 | L36: =MROUND((1+L83)*K36,1) -> 2126 | M36: =(L36/G36)^(1/5)-1 -> 0.10001312
B37: StretchLab | C37: 193 | D37: 358 | E37: 470 | F37: 529 | G37: =MROUND((1+G84)*F37,1) -> 582 | H37: =MROUND((1+H84)*G37,1) -> 611 | I37: =MROUND((1+I84)*H37,1) -> 642 | J37: =MROUND((1+J84)*I37,1) -> 674 | K37: =MROUND((1+K84)*J37,1) -> 708 | L37: =MROUND((1+L84)*K37,1) -> 743 | M37: =(L37/G37)^(1/5)-1 -> 0.050057705
B38: Pure Barre | C38: 591 | D38: 624 | E38: 634 | F38: 626 | G38: =MROUND((1+G85)*F38,1) -> 620 | H38: =MROUND((1+H85)*G38,1) -> 614 | I38: =MROUND((1+I85)*H38,1) -> 608 | J38: =MROUND((1+J85)*I38,1) -> 602 | K38: =MROUND((1+K85)*J38,1) -> 596 | L38: =MROUND((1+L85)*K38,1) -> 590 | M38: =(L38/G38)^(1/5)-1 -> -0.0098703534
B39: YogaSix | C39: 109 | D39: 178 | E39: 191 | F39: 194 | G39: =G40-SUM(G36:G38) -> 197 | H39: =MROUND((1+H86)*G39,1) -> 200 | I39: =MROUND((1+I86)*H39,1) -> 203 | J39: =MROUND((1+J86)*I39,1) -> 206 | K39: =MROUND((1+K86)*J39,1) -> 209 | L39: =MROUND((1+L86)*K39,1) -> 212 | M39: =(L39/G39)^(1/5)-1 -> 0.014784738
B40: Total | C40: =SUM(C36:C39) -> 1619 | D40: =SUM(D36:D39) -> 2113 | E40: =SUM(E36:E39) -> 2404 | F40: =SUM(F36:F39) -> 2549 | G40: =F40+170 -> 2719 | H40: =SUM(H36:H39) -> 2877 | I40: =SUM(I36:I39) -> 3050 | J40: =SUM(J36:J39) -> 3239 | K40: =SUM(K36:K39) -> 3446 | L40: =SUM(L36:L39) -> 3671 | M40: =(L40/G40)^(1/5)-1 -> 0.061879008
B42: Systemwide Sales
B43: Club Pilates | E43: =E50*E36/1000 -> 790.49256 | F43: 958 | G43: =G50*G36/1000 -> 1085.414 | H43: =H50*H36/1000 -> 1229.7741 | I43: =I50*I36/1000 -> 1393.1595 | J43: =J50*J36/1000 -> 1578.7193 | K43: =K50*K36/1000 -> 1788.9666 | L43: =L50*L36/1000 -> 2026.6132 | M43: =(L43/G43)^(1/5)-1 -> 0.13301352
B44: StretchLab | E44: =E51*E37/1000 -> 243.15988 | F44: 260 | G44: =G51*G37/1000 -> 286.04915 | H44: =H51*H37/1000 -> 300.30246 | I44: =I51*I37/1000 -> 315.53875 | J44: =J51*J37/1000 -> 331.26654 | K44: =K51*K37/1000 -> 347.97732 | L44: =L51*L37/1000 -> 365.17958 | M44: =(L44/G44)^(1/5)-1 -> 0.050057705
B45: Pure Barre | E45: =E52*E38/1000 -> 224.1881 | F45: 228 | G45: =G52*G38/1000 -> 225.8147 | H45: =H52*H38/1000 -> 223.62939 | I45: =I52*I38/1000 -> 221.44409 | J45: =J52*J38/1000 -> 219.25879 | K45: =K52*K38/1000 -> 217.07348 | L45: =L52*L38/1000 -> 214.88818 | M45: =(L45/G45)^(1/5)-1 -> -0.0098703534
B46: YogaSix | E46: =E53*E39/1000 -> 83.592686 | F46: 90 | G46: =G53*G39/1000 -> 91.391753 | H46: =H53*H39/1000 -> 92.783505 | I46: =I53*I39/1000 -> 94.175258 | J46: =J53*J39/1000 -> 95.56701 | K46: =K53*K39/1000 -> 96.958763 | L46: =L53*L39/1000 -> 98.350515 | M46: =(L46/G46)^(1/5)-1 -> 0.014784738
...

Sheet ST
A2: =Summary!C8 -> 46113 | B2: Current Capitalization
B3: Current Share Price | F3: =32.45 -> 32.45
B4: Diluted Shares Outstanding | F4: 145.7
B5: Market Cap | F5: =F3*F4 -> 4727.965
B6: (+) Debt | F6: =3203.2 -> 3203.2
B7: (-) Cash | F7: -791.3
B8: TEV | F8: =SUM(F5:F7) -> 7139.865
B9: 2025E EV / EBITDA | F9: =F8/E42 -> 8.3720656
B10: 2026E EV / EBITDA | F10: =F8/F42 -> 8.0061281
A12: =Summary!G8 -> 47848 | B12: Exit
B13: 2030E EBITDA | F13: =J42 -> 1442.0024
B14: EV / EBITDA | F14: =Summary!H8 -> 10
B15: TEV | F15: =F13*F14 -> 14420.024
B16: (-) Current Net Debt | F16: =-F6 -> -3203.2
B17: (+) Cumulative Levered FCF | F17: =F33 -> 3601.8399
B18: Market Cap | F18: =SUM(F15:F17) -> 14818.664
B19: Current Shares Outstanding | F19: =F4 -> 145.7
B20: Implied Share Price | F20: =F18/F19 -> 101.70669
B22: Remaining Upside
B23: Gross Upside | F23: =F20/F3-1 -> 2.1342584
B24: MOIC | F24: =F20/F3 -> 3.1342584
A25: =(A12-A2)/365 -> 4.7534247 | B25: IRR | F25: =F24^(1/A25)-1 -> 0.27166928
B27: Memo: Cash Flows
B28: Cumulative EBITDA | F28: =SUM(F42:J42) -> 5626.2186
B29: Cumulative D&A | F29: =SUM(F46:J46) -> 4077.8812
A30: 200 | B30: Cumulative Interest Expense | F30: =A30*5 -> 1000
B31: Cumulative Capex | F31: =SUM(F49:J49) -> 714.71121
A32: 0.2 | B32: Cumulative Taxes | F32: =(F28-F29)*A32 -> 309.66747
B33: Cumulative Levered FCF | F33: =F28-SUM(F30:F32) -> 3601.8399
K35: '25E - '30E
C36: 2023A | D36: 2024A | E36: 2025E | F36: 2026E | G36: 2027E | H36: 2028E | I36: 2029E | J36: 2030E | K36: CAGR
B37: Revenue
B38: Total | C38: 4054.1 | D38: 3932.8 | E38: 3694.28 | F38: 3810.36 | G38: 4007.98 | H38: =G38*(1+H39) -> 4609.177 | I38: =H38*(1+I39) -> 5300.5535 | J38: =I38*(1+J39) -> 6095.6366 | K38: =(J38/E38)^(1/5)-1 -> 0.105345
B39: % Growth | D39: =D38/C38-1 -> -0.029920328 | E39: =E38/D38-1 -> -0.060648902 | F39: =F38/E38-1 -> 0.031421549 | G39: =G38/F38-1 -> 0.051863866 | H39: 0.15 | I39: 0.15 | J39: 0.15
B41: EBITDA
B42: Total | C42: 878.8 | D42: 764.4 | E42: 852.82 | F42: 891.8 | G42: 948.14 | H42: =G42*(1+H43) -> 1090.361 | I42: =H42*(1+I43) -> 1253.9152 | J42: =I42*(1+J43) -> 1442.0024 | K42: =(J42/E42)^(1/5)-1 -> 0.11076381
B43: % Growth | D43: =D42/C42-1 -> -0.13017751 | E43: =E42/D42-1 -> 0.11567242 | F43: =F42/E42-1 -> 0.045707183 | G43: =G42/F42-1 -> 0.0631756 | H43: 0.15 | I43: 0.15 | J43: 0.15
B44: % Margin | C44: =C42/C38 -> 0.21676821 | D44: =D42/D38 -> 0.19436534 | E44: =E42/E38 -> 0.23084877 | F44: =F42/F38 -> 0.23404613 | G44: =G42/G38 -> 0.23656306 | H44: =H42/H38 -> 0.23656306 | I44: =I42/I38 -> 0.23656306 | J44: =J42/J38 -> 0.23656306
B46: D&A | C46: 300.8 | D46: 307.7 | E46: 600 | F46: =E46*1.12 -> 672 | G46: =F46*1.015 -> 682.08 | H46: =H47*H38 -> 784.392 | I46: =I47*I38 -> 902.0508 | J46: =J47*J38 -> 1037.3584 | K46: =(J46/E46)^(1/5)-1 -> 0.11572077
B47: % Revenue | C47: =C46/C38 -> 0.074196492 | D47: =D46/D38 -> 0.078239422 | E47: =E46/E38 -> 0.16241324 | F47: =F46/F38 -> 0.17636129 | G47: =G46/G38 -> 0.17018049 | H47: =G47 -> 0.17018049 | I47: =H47 -> 0.17018049 | J47: =I47 -> 0.17018049
...

Sheet RDDT
B1: (USD $M, FYE December) | C1: FY2022A | D1: FY2023A | E1: FY2024A | F1: FY2025A | G1: FY2026E | H1: FY2027E | I1: FY2028E | J1: FY2029E | K1: FY2030E | L1: '26E-'30E
B2: Revenue
B3: Advertising | C3: 580 | D3: 758 | E3: 1119 | F3: 1834 | G3: 2580 | H3: 3354 | I3: 4191 | J3: 5113 | K3: 6084
B4: Data Licensing | C4: 0 | D4: 0 | E4: 138 | F4: 313 | G4: 470 | H4: 610 | I4: 815 | J4: 1050 | K4: 1310
B5: Other Revenue | C5: 87 | D5: 46 | E5: 43 | F5: 56 | G5: 92 | H5: 128 | I5: 165 | J5: 197 | K5: 238
B6: Consolidated Total | C6: =SUM(C3:C5) -> 667 | D6: =SUM(D3:D5) -> 804 | E6: =SUM(E3:E5) -> 1300 | F6: =SUM(F3:F5) -> 2203 | G6: =SUM(G3:G5) -> 3142 | H6: =SUM(H3:H5) -> 4092 | I6: =SUM(I3:I5) -> 5171 | J6: =SUM(J3:J5) -> 6360 | K6: =SUM(K3:K5) -> 7632 | L6: =(K6/G6)^(1/4)-1 -> 0.24841232
B8: Revenue - YoY Growth %
B9: Advertising | D9: =IFERROR(D3/C3-1,"-") -> 0.30689655 | E9: =IFERROR(E3/D3-1,"-") -> 0.4762533 | F9: =IFERROR(F3/E3-1,"-") -> 0.63896336 | G9: =IFERROR(G3/F3-1,"-") -> 0.40676118 | H9: =IFERROR(H3/G3-1,"-") -> 0.3 | I9: =IFERROR(I3/H3-1,"-") -> 0.24955277 | J9: =IFERROR(J3/I3-1,"-") -> 0.21999523 | K9: =IFERROR(K3/J3-1,"-") -> 0.18990808
B10: Data Licensing | D10: =IFERROR(D4/C4-1,"-") -> - | E10: =IFERROR(E4/D4-1,"-") -> - | F10: =IFERROR(F4/E4-1,"-") -> 1.2681159 | G10: =IFERROR(G4/F4-1,"-") -> 0.50159744 | H10: =IFERROR(H4/G4-1,"-") -> 0.29787234 | I10: =IFERROR(I4/H4-1,"-") -> 0.33606557 | J10: =IFERROR(J4/I4-1,"-") -> 0.28834356 | K10: =IFERROR(K4/J4-1,"-") -> 0.24761905
B11: Other Revenue | D11: =IFERROR(D5/C5-1,"-") -> -0.47126437 | E11: =IFERROR(E5/D5-1,"-") -> -0.065217391 | F11: =IFERROR(F5/E5-1,"-") -> 0.30232558 | G11: =IFERROR(G5/F5-1,"-") -> 0.64285714 | H11: =IFERROR(H5/G5-1,"-") -> 0.39130435 | I11: =IFERROR(I5/H5-1,"-") -> 0.2890625 | J11: =IFERROR(J5/I5-1,"-") -> 0.19393939 | K11: =IFERROR(K5/J5-1,"-") -> 0.20812183
B12: Consolidated Total | D12: =IFERROR(D6/C6-1,"-") -> 0.2053973 | E12: =IFERROR(E6/D6-1,"-") -> 0.61691542 | F12: =IFERROR(F6/E6-1,"-") -> 0.69461538 | G12: =IFERROR(G6/F6-1,"-") -> 0.42623695 | H12: =IFERROR(H6/G6-1,"-") -> 0.30235519 | I12: =IFERROR(I6/H6-1,"-") -> 0.26368524 | J12: =IFERROR(J6/I6-1,"-") -> 0.22993618 | K12: =IFERROR(K6/J6-1,"-") -> 0.2
B14: Revenue Mix %
B15: Advertising | C15: =IFERROR(C3/C6,"-") -> 0.86956522 | D15: =IFERROR(D3/D6,"-") -> 0.94278607 | E15: =IFERROR(E3/E6,"-") -> 0.86076923 | F15: =IFERROR(F3/F6,"-") -> 0.83250113 | G15: =IFERROR(G3/G6,"-") -> 0.82113304 | H15: =IFERROR(H3/H6,"-") -> 0.81964809 | I15: =IFERROR(I3/I6,"-") -> 0.81048153 | J15: =IFERROR(J3/J6,"-") -> 0.80393082 | K15: =IFERROR(K3/K6,"-") -> 0.79716981
B16: Data Licensing | C16: =IFERROR(C4/C6,"-") -> 0 | D16: =IFERROR(D4/D6,"-") -> 0 | E16: =IFERROR(E4/E6,"-") -> 0.10615385 | F16: =IFERROR(F4/F6,"-") -> 0.14207898 | G16: =IFERROR(G4/G6,"-") -> 0.14958625 | H16: =IFERROR(H4/H6,"-") -> 0.14907136 | I16: =IFERROR(I4/I6,"-") -> 0.15760975 | J16: =IFERROR(J4/J6,"-") -> 0.16509434 | K16: =IFERROR(K4/K6,"-") -> 0.1716457
B17: Other Revenue | C17: =IFERROR(C5/C6,"-") -> 0.13043478 | D17: =IFERROR(D5/D6,"-") -> 0.05721393 | E17: =IFERROR(E5/E6,"-") -> 0.033076923 | F17: =IFERROR(F5/F6,"-") -> 0.025419882 | G17: =IFERROR(G5/G6,"-") -> 0.029280713 | H17: =IFERROR(H5/H6,"-") -> 0.031280547 | I17: =IFERROR(I5/I6,"-") -> 0.031908722 | J17: =IFERROR(J5/J6,"-") -> 0.030974843 | K17: =IFERROR(K5/K6,"-") -> 0.031184486
B18: Total | C18: =IFERROR(C6/C6,"-") -> 1 | D18: =IFERROR(D6/D6,"-") -> 1 | E18: =IFERROR(E6/E6,"-") -> 1 | F18: =IFERROR(F6/F6,"-") -> 1 | G18: =IFERROR(G6/G6,"-") -> 1 | H18: =IFERROR(H6/H6,"-") -> 1 | I18: =IFERROR(I6/I6,"-") -> 1 | J18: =IFERROR(J6/J6,"-") -> 1 | K18: =IFERROR(K6/K6,"-") -> 1
B20: Key Operating Metrics
B21: DAUq (M) | D21: 52 | E21: 82 | F21: 101 | G21: 118 | H21: 135 | I21: 152 | J21: 168 | K21: 182
B22: DAUq YoY Growth | E22: =IFERROR(E21/D21-1,"-") -> 0.57692308 | F22: =IFERROR(F21/E21-1,"-") -> 0.23170732 | G22: =IFERROR(G21/F21-1,"-") -> 0.16831683 | H22: =IFERROR(H21/G21-1,"-") -> 0.1440678 | I22: =IFERROR(I21/H21-1,"-") -> 0.12592593 | J22: =IFERROR(J21/I21-1,"-") -> 0.10526316 | K22: =IFERROR(K21/J21-1,"-") -> 0.083333333
B23: Global ARPU ($) | D23: =IFERROR(D6/D21,"-") -> 15.461538 | E23: =IFERROR(E6/E21,"-") -> 15.853659 | F23: =IFERROR(F6/F21,"-") -> 21.811881 | G23: =IFERROR(G6/G21,"-") -> 26.627119 | H23: =IFERROR(H6/H21,"-") -> 30.311111 | I23: =IFERROR(I6/I21,"-") -> 34.019737 | J23: =IFERROR(J6/J21,"-") -> 37.857143 | K23: =IFERROR(K6/K21,"-") -> 41.934066
B24: ARPU YoY Growth | E24: =IFERROR(E23/D23-1,"-") -> 0.025361 | F24: =IFERROR(F23/E23-1,"-") -> 0.37582635 | G24: =IFERROR(G23/F23-1,"-") -> 0.22076213 | H24: =IFERROR(H23/G23-1,"-") -> 0.1383549 | I24: =IFERROR(I23/H23-1,"-") -> 0.12235202 | J24: =IFERROR(J23/I23-1,"-") -> 0.1127994 | K24: =IFERROR(K23/J23-1,"-") -> 0.10769231
B26: Cost Structure
B27: Cost of Revenue | C27: 119 | D27: 131 | E27: 153 | F27: 194 | G27: 275 | H27: 350 | I27: 430 | J27: 510 | K27: 595
B28: Gross Profit | C28: =C6-C27 -> 548 | D28: =D6-D27 -> 673 | E28: =E6-E27 -> 1147 | F28: =F6-F27 -> 2009 | G28: =G6-G27 -> 2867 | H28: =H6-H27 -> 3742 | I28: =I6-I27 -> 4741 | J28: =J6-J27 -> 5850 | K28: =K6-K27 -> 7037
B29: Gross Margin | C29: =IFERROR(C28/C6,"-") -> 0.82158921 | D29: =IFERROR(D28/D6,"-") -> 0.83706468 | E29: =IFERROR(E28/E6,"-") -> 0.88230769 | F29: =IFERROR(F28/F6,"-") -> 0.91193827 | G29: =IFERROR(G28/G6,"-") -> 0.91247613 | H29: =IFERROR(H28/H6,"-") -> 0.91446725 | I29: =IFERROR(I28/I6,"-") -> 0.91684394 | J29: =IFERROR(J28/J6,"-") -> 0.91981132 | K29: =IFERROR(K28/K6,"-") -> 0.92203878
B31: Operating Expenses
B32: R&D | C32: 477 | D32: 468 | E32: 1155 | F32: 981 | G32: 1080 | H32: 1230 | I32: 1400 | J32: 1570 | K32: 1720
B33: % of Revenue | C33: =IFERROR(C32/C6,"-") -> 0.71514243 | D33: =IFERROR(D32/D6,"-") -> 0.58208955 | E33: =IFERROR(E32/E6,"-") -> 0.88846154 | F33: =IFERROR(F32/F6,"-") -> 0.44530186 | G33: =IFERROR(G32/G6,"-") -> 0.34373011 | H33: =IFERROR(H32/H6,"-") -> 0.30058651 | I33: =IFERROR(I32/I6,"-") -> 0.27074067 | J33: =IFERROR(J32/J6,"-") -> 0.24685535 | K33: =IFERROR(K32/K6,"-") -> 0.22536688
B34: S&M | C34: 86 | D34: 100 | E34: 153 | F34: 178 | G34: 260 | H34: 320 | I34: 380 | J34: 435 | K34: 490
B35: % of Revenue | C35: =IFERROR(C34/C6,"-") -> 0.12893553 | D35: =IFERROR(D34/D6,"-") -> 0.12437811 | E35: =IFERROR(E34/E6,"-") -> 0.11769231 | F35: =IFERROR(F34/F6,"-") -> 0.080798911 | G35: =IFERROR(G34/G6,"-") -> 0.082749841 | H35: =IFERROR(H34/H6,"-") -> 0.078201369 | I35: =IFERROR(I34/I6,"-") -> 0.073486753 | J35: =IFERROR(J34/J6,"-") -> 0.068396226 | K35: =IFERROR(K34/K6,"-") -> 0.064203354
B36: G&A | C36: 168 | D36: 198 | E36: 525 | F36: 263 | G36: 290 | H36: 330 | I36: 360 | J36: 390 | K36: 420
B37: % of Revenue | C37: =IFERROR(C36/C6,"-") -> 0.25187406 | D37: =IFERROR(D36/D6,"-") -> 0.24626866 | E37: =IFERROR(E36/E6,"-") -> 0.40384615 | F37: =IFERROR(F36/F6,"-") -> 0.11938266 | G37: =IFERROR(G36/G6,"-") -> 0.092297899 | H37: =IFERROR(H36/H6,"-") -> 0.080645161 | I37: =IFERROR(I36/I6,"-") -> 0.069619029 | J37: =IFERROR(J36/J6,"-") -> 0.061320755 | K37: =IFERROR(K36/K6,"-") -> 0.055031447
B38: Total OpEx | C38: =C32+C34+C36 -> 731 | D38: =D32+D34+D36 -> 766 | E38: =E32+E34+E36 -> 1833 | F38: =F32+F34+F36 -> 1422 | G38: =G32+G34+G36 -> 1630 | H38: =H32+H34+H36 -> 1880 | I38: =I32+I34+I36 -> 2140 | J38: =J32+J34+J36 -> 2395 | K38: =K32+K34+K36 -> 2630
B40: EBITDA | C40: =C28-C38 -> -183 | D40: =D28-D38 -> -93 | E40: =E28-E38 -> -686 | F40: =F28-F38 -> 587 | G40: =G28-G38 -> 1237 | H40: =H28-H38 -> 1862 | I40: =I28-I38 -> 2601 | J40: =J28-J38 -> 3455 | K40: =K28-K38 -> 4407 | L40: =(K40/G40)^(1/4)-1 -> 0.37386272
B41: EBITDA Margin | C41: =IFERROR(C40/C6,"-") -> -0.27436282 | D41: =IFERROR(D40/D6,"-") -> -0.11567164 | E41: =IFERROR(E40/E6,"-") -> -0.52769231 | F41: =IFERROR(F40/F6,"-") -> 0.26645483 | G41: =IFERROR(G40/G6,"-") -> 0.39369828 | H41: =IFERROR(H40/H6,"-") -> 0.45503421 | I41: =IFERROR(I40/I6,"-") -> 0.50299749 | J41: =IFERROR(J40/J6,"-") -> 0.54323899 | K41: =IFERROR(K40/K6,"-") -> 0.57743711
B42: EBITDA YoY Growth | D42: =IFERROR(D40/C40-1,"-") -> -0.49180328 | E42: =IFERROR(E40/D40-1,"-") -> 6.3763441 | F42: =IFERROR(F40/E40-1,"-") -> -1.8556851 | G42: =IFERROR(G40/F40-1,"-") -> 1.1073254 | H42: =IFERROR(H40/G40-1,"-") -> 0.50525465 | I42: =IFERROR(I40/H40-1,"-") -> 0.39688507 | J42: =IFERROR(J40/I40-1,"-") -> 0.32833526 | K42: =IFERROR(K40/J40-1,"-") -> 0.27554269
B44: D&A | C44: 11 | D44: 14 | E44: 16 | F44: 16 | G44: 18 | H44: 20 | I44: 23 | J44: 26 | K44: 30
B45: % of Revenue | C45: =IFERROR(C44/C6,"-") -> 0.016491754 | D45: =IFERROR(D44/D6,"-") -> 0.017412935 | E45: =IFERROR(E44/E6,"-") -> 0.012307692 | F45: =IFERROR(F44/F6,"-") -> 0.0072628234 | G45: =IFERROR(G44/G6,"-") -> 0.0057288351 | H45: =IFERROR(H44/H6,"-") -> 0.0048875855 | I45: =IFERROR(I44/I6,"-") -> 0.0044478824 | J45: =IFERROR(J44/J6,"-") -> 0.0040880503 | K45: =IFERROR(K44/K6,"-") -> 0.0039308176
B47: Capital Expenditure | C47: 8 | D47: 10 | E47: 6 | F47: 7 | G47: 10 | H47: 12 | I47: 15 | J47: 19 | K47: 23
B48: % of Revenue | C48: =IFERROR(C47/C6,"-") -> 0.011994003 | D48: =IFERROR(D47/D6,"-") -> 0.012437811 | E48: =IFERROR(E47/E6,"-") -> 0.0046153846 | F48: =IFERROR(F47/F6,"-") -> 0.0031774852 | G48: =IFERROR(G47/G6,"-") -> 0.0031826862 | H48: =IFERROR(H47/H6,"-") -> 0.0029325513 | I48: =IFERROR(I47/I6,"-") -> 0.0029007929 | J48: =IFERROR(J47/J6,"-") -> 0.0029874214 | K48: =IFERROR(K47/K6,"-") -> 0.0030136268
...
